File: raw-data/Sp15_245L_sec-001_group-01_bendtest-tungsten_copy.raw
"Test Type","Manual"
"Method Name:","C:\INSTRON\user\template\245L-Mod01.mtM"
"Name:","4FtPerMin"
"Operator ID:","Jaques"
"Company:","BSU"
"Lab name:",""
"Test date:","1/26/15"
"Temperature:",""
"Humidity:",""
"Note 1:",""
"Note 2:",""
"Note 3:",""
"Geometry:","Circular"
"Specimen",1
"Specimen name:",""
"Width:",6.350000,"mm"
"Thickness:",1.524000,"mm"
"Length:",12.000000,"mm"
"Diameter:",5.000000,"um"
"Inner diameter:",0.500000,"mm"
"Outer diameter:",1.000000,"mm"
"Wall thickness:",0.500000,"mm"
"Area:",19.634954,"um*um"
"Linear density:",1.000000,"den"
"Sled weight:",9.806650,"N"
"Loading span:",0.000000,"mm"
"Support span:",1.000000,"mm"
"Span ratio:","2"
"Fixture type:","3-point"
"Comment:",""
"Included"
"Time sec","Extension mm","Load N","Stress MPa","Cycle Count ","Total Cycle Count ","Repetitions Count ","Strain [Exten.] %","Tenacity gf/tex"
0,0,-5.158131,-262701.5,0,0,0,0,-4733.847
0.008,0,-5.18056,-263843.8,0,0,0,0,-4754.431
0.016,0,-5.202673,-264970,0,0,0,0,-4774.725
0.04,0,-5.175682,-263595.3,0,0,0,0,-4749.955
0.048,0,-5.145434,-262054.8,0,0,0,0,-4722.194
0.058,0,-5.117828,-260648.8,0,0,0,0,-4696.859
0.072,0,-5.09447,-259459.3,0,0,0,0,-4675.423
0.088,0,-5.120175,-260768.4,0,0,0,0,-4699.013
0.096,0,-5.154797,-262531.7,0,0,0,0,-4730.788
0.104,0,-5.188565,-264251.4,0,0,0,0,-4761.777
0.114,0,-5.214144,-265554.2,0,0,0,0,-4785.252
0.134,0,-5.187225,-264183.2,0,0,0,0,-4760.547
0.142,0,-5.15866,-262728.4,0,0,0,0,-4734.333
0.15,0,-5.134578,-261501.9,0,0,0,0,-4712.231
0.178,0,-5.137197,-261635.3,0,0,0,0,-4714.635
0.186,0,-5.160599,-262827.1,0,0,0,0,-4736.111
0.194,0,-5.187614,-264203,0,0,0,0,-4760.905
0.202,0,-5.213746,-265533.9,0,0,0,0,-4784.888
0.212,0,-5.237714,-266754.6,0,0,0,0,-4806.884
0.236,-0.000472222,-5.234548,-266593.4,0,0,0,-0.003935183,-4803.979
0.248,-0.000472222,-5.207865,-265234.4,0,0,0,-0.003935183,-4779.49
0.268,-0.000472222,-5.211303,-265409.5,0,0,0,-0.003935183,-4782.646
0.276,-0.000472222,-5.244649,-267107.8,0,0,0,-0.003935183,-4813.248
0.284,-0.000472222,-5.282174,-269018.9,0,0,0,-0.003935183,-4847.687
0.292,-0.0007083331,-5.311153,-270494.8,0,0,0,-0.005902776,-4874.282
0.302,-0.0007083331,-5.332122,-271562.7,0,0,0,-0.005902776,-4893.526
0.316,-0.0007083331,-5.353149,-272633.7,0,0,0,-0.005902776,-4912.824
0.338,-0.000944444,-5.361426,-273055.2,0,0,0,-0.007870367,-4920.42
0.364,-0.000944444,-5.397739,-274904.6,0,0,0,-0.007870367,-4953.746
0.368,-0.000944444,-5.420964,-276087.4,0,0,0,-0.007870367,-4975.06
0.372,-0.000944444,-5.443546,-277237.5,0,0,0,-0.007870367,-4995.785
0.378,-0.000944444,-5.472879,-278731.4,0,0,0,-0.007870367,-5022.705
0.386,-0.000944444,-5.499236,-280073.8,0,0,0,-0.007870367,-5046.894
0.414,-0.000944444,-5.499003,-280061.9,0,0,0,-0.007870367,-5046.681
0.434,-0.001180555,-5.508166,-280528.6,0,0,0,-0.009837959,-5055.09
0.44,-0.001416666,-5.523404,-281304.7,0,0,0,-0.01180555,-5069.074
0.448,-0.001652777,-5.556521,-282991.3,0,0,0,-0.01377314,-5099.467
0.456,-0.001652777,-5.596078,-285005.9,0,0,0,-0.01377314,-5135.77
0.462,-0.001888888,-5.624535,-286455.2,0,0,0,-0.01574073,-5161.886
0.47,-0.002124999,-5.660256,-288274.5,0,0,0,-0.01770833,-5194.669
0.478,-0.00236111,-5.695934,-290091.5,0,0,0,-0.01967592,-5227.413
0.484,-0.002597221,-5.723081,-291474.1,0,0,0,-0.02164351,-5252.326
0.492,-0.002833332,-5.755965,-293148.9,0,0,0,-0.0236111,-5282.505
0.5,-0.003069443,-5.783865,-294569.8,0,0,0,-0.02557869,-5308.111
0.508,-0.003305554,-5.806889,-295742.4,0,0,0,-0.02754628,-5329.241
0.516,-0.003541665,-5.831568,-296999.3,0,0,0,-0.02951388,-5351.89
0.522,-0.003777776,-5.852336,-298057,0,0,0,-0.03148147,-5370.949
0.53,-0.004013887,-5.887353,-299840.4,0,0,0,-0.03344906,-5403.086
0.534,-0.004249998,-5.908309,-300907.7,0,0,0,-0.03541665,-5422.318
0.538,-0.004249998,-5.931352,-302081.3,0,0,0,-0.03541665,-5443.466
0.542,-0.004486109,-5.95429,-303249.5,0,0,0,-0.03738425,-5464.517
0.548,-0.00472222,-5.983495,-304736.9,0,0,0,-0.03935184,-5491.32
0.556,-0.00472222,-6.013827,-306281.7,0,0,0,-0.03935184,-5519.158
0.562,-0.004958331,-6.034987,-307359.3,0,0,0,-0.04131943,-5538.576
0.57,-0.005194443,-6.063282,-308800.4,0,0,0,-0.04328702,-5564.544
0.578,-0.005430553,-6.097413,-310538.7,0,0,0,-0.04525461,-5595.868
0.586,-0.005430553,-6.134641,-312434.7,0,0,0,-0.04525461,-5630.034
0.592,-0.005666665,-6.157402,-313593.9,0,0,0,-0.0472222,-5650.922
0.6,-0.005902775,-6.178515,-314669.2,0,0,0,-0.04918979,-5670.298
0.614,-0.006138886,-6.19599,-315559.2,0,0,0,-0.05115739,-5686.336
0.628,-0.006138886,-6.218358,-316698.4,0,0,0,-0.05115739,-5706.865
0.638,-0.006374997,-6.236717,-317633.4,0,0,0,-0.05312498,-5723.713
0.65,-0.006611108,-6.258352,-318735.3,0,0,0,-0.05509257,-5743.569
0.664,-0.006611108,-6.282691,-319974.8,0,0,0,-0.05509257,-5765.906
0.674,-0.00684722,-6.302278,-320972.4,0,0,0,-0.05706016,-5783.881
0.698,-0.00708333,-6.316108,-321676.8,0,0,0,-0.05902775,-5796.574
0.714,-0.00708333,-6.294894,-320596.3,0,0,0,-0.05902775,-5777.105
0.73,-0.007319441,-6.309759,-321353.4,0,0,0,-0.06099534,-5790.748
0.742,-0.007319441,-6.339482,-322867.2,0,0,0,-0.06099534,-5818.025
0.748,-0.007555552,-6.355287,-323672.1,0,0,0,-0.06296293,-5832.53
0.756,-0.007555552,-6.380172,-324939.5,0,0,0,-0.06296293,-5855.369
0.764,-0.007555552,-6.405524,-326230.6,0,0,0,-0.06296293,-5878.635
0.774,-0.007555552,-6.429263,-327439.7,0,0,0,-0.06296293,-5900.422
0.788,-0.007791664,-6.443797,-328179.9,0,0,0,-0.06493053,-5913.76
0.816,-0.008027775,-6.43818,-327893.8,0,0,0,-0.06689812,-5908.605
0.834,-0.008263885,-6.423255,-327133.7,0,0,0,-0.06886571,-5894.908
0.844,-0.008263885,-6.44652,-328318.6,0,0,0,-0.06886571,-5916.259
0.852,-0.008263885,-6.47263,-329648.3,0,0,0,-0.06886571,-5940.221
0.86,-0.008263885,-6.500449,-331065.2,0,0,0,-0.06886571,-5965.752
0.866,-0.008499997,-6.517334,-331925.1,0,0,0,-0.0708333,-5981.249
0.88,-0.008499997,-6.540902,-333125.4,0,0,0,-0.0708333,-6002.878
0.916,-0.008972219,-6.54109,-333135,0,0,0,-0.07476849,-6003.05
0.93,-0.008972219,-6.563745,-334288.8,0,0,0,-0.07476849,-6023.841
0.94,-0.008972219,-6.58825,-335536.8,0,0,0,-0.07476849,-6046.331
0.946,-0.00920833,-6.603541,-336315.6,0,0,0,-0.07673608,-6060.364
0.958,-0.00920833,-6.630046,-337665.5,0,0,0,-0.07673608,-6084.689
0.978,-0.00944444,-6.653772,-338873.8,0,0,0,-0.07870367,-6106.463
1.008,-0.009916663,-6.663936,-339391.5,0,0,0,-0.08263886,-6115.792
1.024,-0.009916663,-6.686288,-340529.9,0,0,0,-0.08263886,-6136.305
1.034,-0.01015277,-6.710946,-341785.7,0,0,0,-0.08460645,-6158.935
1.044,-0.01015277,-6.736059,-343064.7,0,0,0,-0.08460645,-6181.981
1.056,-0.01038889,-6.761794,-344375.4,0,0,0,-0.08657404,-6205.6
1.068,-0.01038889,-6.787879,-345703.9,0,0,0,-0.08657404,-6229.54
1.086,-0.010625,-6.807928,-346724.9,0,0,0,-0.08854163,-6247.938
1.114,-0.01086111,-6.821613,-347421.9,0,0,0,-0.09050922,-6260.498
1.128,-0.01109722,-6.835866,-348147.8,0,0,0,-0.09247681,-6273.579
1.142,-0.01133333,-6.861054,-349430.6,0,0,0,-0.09444441,-6296.695
1.154,-0.01133333,-6.889865,-350897.9,0,0,0,-0.09444441,-6323.136
1.166,-0.01156944,-6.912172,-352034.1,0,0,0,-0.096412,-6343.609
1.188,-0.01180555,-6.930307,-352957.7,0,0,0,-0.09837959,-6360.252
1.202,-0.01180555,-6.951846,-354054.6,0,0,0,-0.09837959,-6380.019
1.214,-0.01204166,-6.966204,-354785.8,0,0,0,-0.1003472,-6393.196
1.236,-0.01227777,-6.986992,-355844.6,0,0,0,-0.1023148,-6412.274
1.248,-0.01227777,-7.012792,-357158.6,0,0,0,-0.1023148,-6435.952
1.26,-0.01251388,-7.030943,-358083,0,0,0,-0.1042824,-6452.61
1.294,-0.01274999,-7.042063,-358649.3,0,0,0,-0.10625,-6462.815
1.306,-0.01298611,-7.063994,-359766.3,0,0,0,-0.1082175,-6482.942
1.318,-0.01298611,-7.088593,-361019.1,0,0,0,-0.1082175,-6505.518
1.33,-0.01322222,-7.112421,-362232.6,0,0,0,-0.1101851,-6527.386
1.342,-0.01322222,-7.134819,-363373.4,0,0,0,-0.1101851,-6547.942
1.36,-0.01345833,-7.156055,-364454.9,0,0,0,-0.1121527,-6567.431
1.376,-0.01369444,-7.176428,-365492.5,0,0,0,-0.1141203,-6586.127
1.408,-0.01393055,-7.187552,-366059,0,0,0,-0.1160879,-6596.337
1.418,-0.01393055,-7.211241,-367265.5,0,0,0,-0.1160879,-6618.078
1.426,-0.01416666,-7.227838,-368110.8,0,0,0,-0.1180555,-6633.309
1.442,-0.01440277,-7.250965,-369288.6,0,0,0,-0.1200231,-6654.534
1.462,-0.01440277,-7.274084,-370466.1,0,0,0,-0.1200231,-6675.751
1.472,-0.01463888,-7.288917,-371221.5,0,0,0,-0.1219907,-6689.365
1.488,-0.01487499,-7.305597,-372071,0,0,0,-0.1239583,-6704.672
1.512,-0.0151111,-7.329913,-373309.4,0,0,0,-0.1259259,-6726.988
1.52,-0.0151111,-7.351151,-374391,0,0,0,-0.1259259,-6746.479
1.53,-0.0151111,-7.375155,-375613.6,0,0,0,-0.1259259,-6768.509
1.546,-0.01534721,-7.393064,-376525.7,0,0,0,-0.1278935,-6784.945
1.562,-0.01558333,-7.416267,-377707.4,0,0,0,-0.1298611,-6806.239
1.578,-0.01581944,-7.426969,-378252.4,0,0,0,-0.1318286,-6816.061
1.604,-0.01605555,-7.435337,-378678.6,0,0,0,-0.1337962,-6823.74
1.612,-0.01605555,-7.458893,-379878.3,0,0,0,-0.1337962,-6845.358
1.62,-0.01629166,-7.481257,-381017.3,0,0,0,-0.1357638,-6865.884
1.628,-0.01629166,-7.502705,-382109.6,0,0,0,-0.1357638,-6885.567
1.636,-0.01629166,-7.524264,-383207.6,0,0,0,-0.1357638,-6905.352
1.648,-0.01652777,-7.54306,-384164.9,0,0,0,-0.1377314,-6922.603
1.672,-0.01676388,-7.563653,-385213.7,0,0,0,-0.139699,-6941.502
1.682,-0.01699999,-7.57908,-385999.4,0,0,0,-0.1416666,-6955.66
1.702,-0.01699999,-7.600614,-387096.1,0,0,0,-0.1416666,-6975.423
1.712,-0.0172361,-7.615668,-387862.8,0,0,0,-0.1436342,-6989.238
1.724,-0.01747222,-7.640674,-389136.3,0,0,0,-0.1456018,-7012.187
1.738,-0.01747222,-7.662494,-390247.6,0,0,0,-0.1456018,-7032.212
1.754,-0.01770833,-7.681137,-391197.1,0,0,0,-0.1475694,-7049.322
1.764,-0.01794444,-7.694965,-391901.4,0,0,0,-0.149537,-7062.013
1.78,-0.01794444,-7.716227,-392984.3,0,0,0,-0.149537,-7081.526
1.794,-0.01818055,-7.734694,-393924.7,0,0,0,-0.1515046,-7098.473
1.808,-0.01841666,-7.758967,-395161,0,0,0,-0.1534722,-7120.75
1.82,-0.01841666,-7.779779,-396220.9,0,0,0,-0.1534722,-7139.85
1.832,-0.01865277,-7.790667,-396775.4,0,0,0,-0.1554397,-7149.842
1.868,-0.01888888,-7.806321,-397572.7,0,0,0,-0.1574073,-7164.208
1.884,-0.01912499,-7.827094,-398630.6,0,0,0,-0.1593749,-7183.273
1.898,-0.01912499,-7.854013,-400001.6,0,0,0,-0.1593749,-7207.978
1.908,-0.0193611,-7.874376,-401038.7,0,0,0,-0.1613425,-7226.666
1.92,-0.0193611,-7.901302,-402410,0,0,0,-0.1613425,-7251.377
1.932,-0.01959721,-7.919473,-403335.4,0,0,0,-0.1633101,-7268.053
1.958,-0.01983333,-7.938355,-404297.1,0,0,0,-0.1652777,-7285.382
1.98,-0.01983333,-7.963231,-405564,0,0,0,-0.1652777,-7308.212
1.988,-0.02006944,-7.978803,-406357.1,0,0,0,-0.1672453,-7322.503
2.006,-0.02030555,-7.993884,-407125.2,0,0,0,-0.1692129,-7336.344
2.028,-0.02054166,-8.017532,-408329.5,0,0,0,-0.1711805,-7358.046
2.04,-0.02054166,-8.040489,-409498.7,0,0,0,-0.1711805,-7379.115
2.074,-0.02101388,-8.047251,-409843.1,0,0,0,-0.1751157,-7385.321
2.082,-0.02101388,-8.070986,-411051.9,0,0,0,-0.1751157,-7407.104
2.09,-0.02101388,-8.093439,-412195.5,0,0,0,-0.1751157,-7427.71
2.106,-0.02124999,-8.117845,-413438.5,0,0,0,-0.1770833,-7450.108
2.12,-0.0214861,-8.130793,-414097.9,0,0,0,-0.1790509,-7461.991
2.136,-0.0214861,-8.152767,-415217,0,0,0,-0.1790509,-7482.158
2.16,-0.02172221,-8.173883,-416292.4,0,0,0,-0.1810184,-7501.537
2.174,-0.02195833,-8.194656,-417350.4,0,0,0,-0.1829861,-7520.602
2.182,-0.02195833,-8.215485,-418411.2,0,0,0,-0.1829861,-7539.717
2.19,-0.02219444,-8.233906,-419349.4,0,0,0,-0.1849536,-7556.623
2.204,-0.02219444,-8.256448,-420497.5,0,0,0,-0.1849536,-7577.311
2.222,-0.02243054,-8.279469,-421669.9,0,0,0,-0.1869212,-7598.438
2.238,-0.02266666,-8.295686,-422495.8,0,0,0,-0.1888888,-7613.321
2.258,-0.02266666,-8.318328,-423649,0,0,0,-0.1888888,-7634.101
2.274,-0.02290277,-8.336994,-424599.6,0,0,0,-0.1908564,-7651.231
2.288,-0.02313888,-8.349968,-425260.4,0,0,0,-0.192824,-7663.138
2.31,-0.02337499,-8.370818,-426322.3,0,0,0,-0.1947916,-7682.272
2.34,-0.0236111,-8.392814,-427442.5,0,0,0,-0.1967592,-7702.459
2.348,-0.0236111,-8.416438,-428645.7,0,0,0,-0.1967592,-7724.14
2.356,-0.02384721,-8.437554,-429721.1,0,0,0,-0.1987268,-7743.52
2.376,-0.02408332,-8.458924,-430809.4,0,0,0,-0.2006944,-7763.131
2.392,-0.02408332,-8.484371,-432105.5,0,0,0,-0.2006944,-7786.486
2.404,-0.02431944,-8.50619,-433216.7,0,0,0,-0.202662,-7806.51
2.422,-0.02455555,-8.523372,-434091.8,0,0,0,-0.2046295,-7822.278
2.444,-0.02455555,-8.546841,-435287.1,0,0,0,-0.2046295,-7843.817
2.454,-0.02479165,-8.564019,-436161.9,0,0,0,-0.2065971,-7859.582
2.468,-0.02479165,-8.585784,-437270.4,0,0,0,-0.2065971,-7879.557
2.486,-0.02502777,-8.600147,-438001.9,0,0,0,-0.2085647,-7892.739
2.504,-0.02526388,-8.620278,-439027.2,0,0,0,-0.2105323,-7911.213
2.52,-0.02549999,-8.637306,-439894.4,0,0,0,-0.2124999,-7926.841
2.542,-0.0257361,-8.65277,-440682,0,0,0,-0.2144675,-7941.033
2.554,-0.0257361,-8.677284,-441930.5,0,0,0,-0.2144675,-7963.531
2.566,-0.02597221,-8.6978,-442975.3,0,0,0,-0.2164351,-7982.359
2.592,-0.02620832,-8.718374,-444023.2,0,0,0,-0.2184027,-8001.241
2.61,-0.02620832,-8.741201,-445185.7,0,0,0,-0.2184027,-8022.19
2.622,-0.02644443,-8.766525,-446475.5,0,0,0,-0.2203703,-8045.431
2.638,-0.02668055,-8.790036,-447672.8,0,0,0,-0.2223379,-8067.008
2.668,-0.02691665,-8.812523,-448818.2,0,0,0,-0.2243055,-8087.646
2.682,-0.02691665,-8.837186,-450074.2,0,0,0,-0.2243055,-8110.279
2.696,-0.02715277,-8.853192,-450889.3,0,0,0,-0.2262731,-8124.969
2.71,-0.02738888,-8.870575,-451774.7,0,0,0,-0.2282407,-8140.922
2.726,-0.02738888,-8.891854,-452858.4,0,0,0,-0.2282407,-8160.451
2.756,-0.02762499,-8.912105,-453889.8,0,0,0,-0.2302082,-8179.036
2.764,-0.0278611,-8.924505,-454521.3,0,0,0,-0.2321758,-8190.416
2.776,-0.0278611,-8.953239,-455984.7,0,0,0,-0.2321758,-8216.786
2.798,-0.02809721,-8.972856,-456983.8,0,0,0,-0.2341434,-8234.79
2.814,-0.02833332,-8.99101,-457908.4,0,0,0,-0.236111,-8251.451
2.83,-0.02856943,-9.013205,-459038.8,0,0,0,-0.2380786,-8271.82
2.854,-0.02856943,-9.039802,-460393.4,0,0,0,-0.2380786,-8296.229
2.862,-0.02880554,-9.057887,-461314.4,0,0,0,-0.2400462,-8312.827
2.882,-0.02904166,-9.075821,-462227.8,0,0,0,-0.2420138,-8329.286
2.906,-0.02927776,-9.094995,-463204.3,0,0,0,-0.2439814,-8346.883
2.92,-0.02927776,-9.118414,-464397,0,0,0,-0.2439814,-8368.375
2.93,-0.02951388,-9.134258,-465204,0,0,0,-0.245949,-8382.916
2.944,-0.02951388,-9.155698,-466295.9,0,0,0,-0.245949,-8402.593
2.952,-0.02974999,-9.172251,-467138.9,0,0,0,-0.2479166,-8417.783
2.964,-0.02974999,-9.195131,-468304.2,0,0,0,-0.2479166,-8438.782
3,-0.03022221,-9.213301,-469229.6,0,0,0,-0.2518517,-8455.457
3.024,-0.03045832,-9.22792,-469974.1,0,0,0,-0.2538193,-8468.874
3.044,-0.03045832,-9.252588,-471230.5,0,0,0,-0.2538193,-8491.513
3.052,-0.03069443,-9.268385,-472035,0,0,0,-0.2557869,-8506.011
3.064,-0.03069443,-9.294188,-473349.1,0,0,0,-0.2557869,-8529.69
3.078,-0.03093054,-9.316919,-474506.8,0,0,0,-0.2577545,-8550.553
3.092,-0.03116666,-9.332323,-475291.3,0,0,0,-0.2597221,-8564.688
3.11,-0.03116666,-9.357428,-476569.9,0,0,0,-0.2597221,-8587.729
3.124,-0.03140276,-9.379768,-477707.7,0,0,0,-0.2616897,-8608.231
3.138,-0.03163887,-9.393221,-478392.8,0,0,0,-0.2636573,-8620.577
3.16,-0.03187499,-9.41033,-479264.2,0,0,0,-0.2656249,-8636.279
3.172,-0.03187499,-9.434863,-480513.6,0,0,0,-0.2656249,-8658.795
3.184,-0.0321111,-9.449901,-481279.5,0,0,0,-0.2675925,-8672.596
3.206,-0.0321111,-9.472373,-482424,0,0,0,-0.2675925,-8693.219
3.216,-0.03234721,-9.486106,-483123.4,0,0,0,-0.2695601,-8705.822
3.232,-0.03258332,-9.49959,-483810.2,0,0,0,-0.2715277,-8718.197
3.254,-0.03258332,-9.52418,-485062.5,0,0,0,-0.2715277,-8740.765
3.264,-0.03281943,-9.546426,-486195.5,0,0,0,-0.2734953,-8761.181
3.276,-0.03281943,-9.571058,-487450,0,0,0,-0.2734953,-8783.786
3.294,-0.03305554,-9.589748,-488401.9,0,0,0,-0.2754628,-8800.939
3.32,-0.03329165,-9.606044,-489231.8,0,0,0,-0.2774304,-8815.895
3.332,-0.03352777,-9.619359,-489909.9,0,0,0,-0.2793981,-8828.114
3.346,-0.03376387,-9.640292,-490976.1,0,0,0,-0.2813656,-8847.326
3.36,-0.03376387,-9.662327,-492098.3,0,0,0,-0.2813656,-8867.549
3.368,-0.03399999,-9.67703,-492847.1,0,0,0,-0.2833332,-8881.042
3.38,-0.03399999,-9.700189,-494026.6,0,0,0,-0.2833332,-8902.296
3.41,-0.03447221,-9.705672,-494305.8,0,0,0,-0.2872684,-8907.328
3.43,-0.03447221,-9.729681,-495528.6,0,0,0,-0.2872684,-8929.361
3.442,-0.03470832,-9.759044,-497024.1,0,0,0,-0.289236,-8956.311
3.454,-0.03470832,-9.783863,-498288.1,0,0,0,-0.289236,-8979.088
3.464,-0.03494443,-9.804301,-499329,0,0,0,-0.2912036,-8997.844
3.478,-0.03494443,-9.826284,-500448.5,0,0,0,-0.2912036,-9018.019
3.502,-0.03518054,-9.805392,-499384.5,0,0,0,-0.2931712,-8998.846
3.528,-0.03541665,-9.80164,-499193.4,0,0,0,-0.2951388,-8995.402
3.536,-0.03541665,-9.823821,-500323.1,0,0,0,-0.2951388,-9015.759
3.544,-0.03541665,-9.848092,-501559.2,0,0,0,-0.2951388,-9038.033
3.552,-0.03541665,-9.870213,-502685.8,0,0,0,-0.2951388,-9058.335
3.56,-0.03565276,-9.886663,-503523.7,0,0,0,-0.2971064,-9073.432
3.59,-0.03588887,-9.897371,-504069,0,0,0,-0.299074,-9083.259
3.62,-0.03612498,-9.916247,-505030.3,0,0,0,-0.3010415,-9100.582
3.634,-0.03612498,-9.941307,-506306.6,0,0,0,-0.3010415,-9123.581
3.646,-0.03612498,-9.967474,-507639.3,0,0,0,-0.3010415,-9147.596
3.656,-0.0363611,-9.981814,-508369.6,0,0,0,-0.3030091,-9160.756
3.674,-0.03659721,-10.00124,-509358.8,0,0,0,-0.3049767,-9178.582
3.7,-0.03683332,-10.0188,-510253.3,0,0,0,-0.3069443,-9194.699
3.722,-0.03706943,-10.04167,-511418,0,0,0,-0.3089119,-9215.688
3.742,-0.03706943,-10.06345,-512527.2,0,0,0,-0.3089119,-9235.675
3.75,-0.03730554,-10.08214,-513479.1,0,0,0,-0.3108795,-9252.828
3.762,-0.03730554,-10.11025,-514911,0,0,0,-0.3108795,-9278.631
3.774,-0.03754165,-10.12607,-515716.3,0,0,0,-0.3128471,-9293.143
3.794,-0.03777776,-10.14593,-516728,0,0,0,-0.3148147,-9311.373
3.818,-0.03801387,-10.16609,-517754.7,0,0,0,-0.3167823,-9329.874
3.83,-0.03801387,-10.18931,-518937.4,0,0,0,-0.3167823,-9351.187
3.842,-0.03824999,-10.20427,-519699.2,0,0,0,-0.3187499,-9364.912
3.856,-0.0384861,-10.21759,-520377.5,0,0,0,-0.3207175,-9377.136
3.874,-0.0384861,-10.24171,-521606.1,0,0,0,-0.3207175,-9399.276
3.888,-0.03872221,-10.25812,-522441.9,0,0,0,-0.322685,-9414.337
3.904,-0.03895832,-10.27803,-523456,0,0,0,-0.3246527,-9432.611
3.92,-0.03895832,-10.30134,-524642.8,0,0,0,-0.3246527,-9453.997
3.934,-0.03919443,-10.31975,-525580.5,0,0,0,-0.3266203,-9470.894
3.948,-0.03943054,-10.34017,-526620.4,0,0,0,-0.3285878,-9489.634
3.966,-0.03943054,-10.3627,-527768.1,0,0,0,-0.3285878,-9510.313
3.99,-0.03966665,-10.38201,-528751.6,0,0,0,-0.3305554,-9528.036
4.008,-0.03990276,-10.39583,-529455.3,0,0,0,-0.332523,-9540.717
4.02,-0.04013887,-10.41205,-530281.3,0,0,0,-0.3344906,-9555.603
4.042,-0.04013887,-10.43443,-531421,0,0,0,-0.3344906,-9576.139
4.052,-0.04037498,-10.45042,-532235.3,0,0,0,-0.3364582,-9590.813
4.066,-0.04061109,-10.47239,-533354.4,0,0,0,-0.3384258,-9610.978
4.086,-0.04061109,-10.49579,-534546,0,0,0,-0.3384258,-9632.45
4.098,-0.0408472,-10.5123,-535387.1,0,0,0,-0.3403934,-9647.608
4.112,-0.04108332,-10.52776,-536174.4,0,0,0,-0.342361,-9661.794
4.128,-0.04108332,-10.551,-537358.2,0,0,0,-0.342361,-9683.127
4.136,-0.04131943,-10.56539,-538090.8,0,0,0,-0.3443286,-9696.328
4.154,-0.04131943,-10.58878,-539281.9,0,0,0,-0.3443286,-9717.792
4.168,-0.04155554,-10.6065,-540184.5,0,0,0,-0.3462962,-9734.056
4.184,-0.04179165,-10.62268,-541008.7,0,0,0,-0.3482637,-9748.907
4.208,-0.04202776,-10.63999,-541890.3,0,0,0,-0.3502313,-9764.795
4.22,-0.04202776,-10.66274,-543048.9,0,0,0,-0.3502313,-9785.673
4.25,-0.04226387,-10.68227,-544043.8,0,0,0,-0.3521989,-9803.6
4.262,-0.04249998,-10.69938,-544914.9,0,0,0,-0.3541665,-9819.297
4.276,-0.04273609,-10.71952,-545940.8,0,0,0,-0.3561341,-9837.783
4.296,-0.04273609,-10.7425,-547110.9,0,0,0,-0.3561341,-9858.869
4.304,-0.04297221,-10.7564,-547818.8,0,0,0,-0.3581017,-9871.625
4.316,-0.04297221,-10.78091,-549067.1,0,0,0,-0.3581017,-9894.118
4.33,-0.04320832,-10.80263,-550173.3,0,0,0,-0.3600693,-9914.053
4.344,-0.04344442,-10.81678,-550894.1,0,0,0,-0.3620369,-9927.042
4.362,-0.04344442,-10.83702,-551924.8,0,0,0,-0.3620369,-9945.615
4.376,-0.04368054,-10.86142,-553167.4,0,0,0,-0.3640045,-9968.005
4.402,-0.04391665,-10.88232,-554232,0,0,0,-0.3659721,-9987.19
4.414,-0.04415276,-10.90481,-555377.4,0,0,0,-0.3679397,-10007.83
4.426,-0.04415276,-10.92662,-556488.2,0,0,0,-0.3679397,-10027.85
4.438,-0.04438887,-10.94355,-557350.4,0,0,0,-0.3699073,-10043.38
4.462,-0.04462499,-10.96386,-558384.9,0,0,0,-0.3718749,-10062.03
4.486,-0.04486109,-10.97881,-559146.1,0,0,0,-0.3738424,-10075.74
4.512,-0.0450972,-10.99696,-560070.5,0,0,0,-0.37581,-10092.4
4.528,-0.0450972,-11.02171,-561331.1,0,0,0,-0.37581,-10115.11
4.54,-0.04533332,-11.0425,-562390.1,0,0,0,-0.3777776,-10134.2
4.556,-0.04556942,-11.06384,-563476.9,0,0,0,-0.3797452,-10153.78
4.576,-0.04556942,-11.08717,-564665.1,0,0,0,-0.3797452,-10175.19
4.584,-0.04580554,-11.10178,-565408.9,0,0,0,-0.3817128,-10188.6
4.596,-0.04580554,-11.12404,-566542.7,0,0,0,-0.3817128,-10209.03
4.606,-0.04604165,-11.14182,-567448.4,0,0,0,-0.3836804,-10225.35
4.624,-0.04627776,-11.16503,-568630.5,0,0,0,-0.385648,-10246.65
4.646,-0.04651387,-11.18386,-569589.1,0,0,0,-0.3876156,-10263.92
4.666,-0.04651387,-11.20788,-570812.8,0,0,0,-0.3876156,-10285.97
4.68,-0.04674998,-11.22076,-571468.4,0,0,0,-0.3895831,-10297.79
4.692,-0.04698609,-11.23805,-572349.2,0,0,0,-0.3915508,-10313.66
4.706,-0.04698609,-11.26085,-573510.3,0,0,0,-0.3915508,-10334.58
4.728,-0.0472222,-11.27856,-574412.4,0,0,0,-0.3935184,-10350.84
4.738,-0.04745831,-11.29518,-575258.9,0,0,0,-0.3954859,-10366.09
4.752,-0.04745831,-11.31539,-576288.1,0,0,0,-0.3954859,-10384.64
4.768,-0.04769443,-11.33362,-577216.8,0,0,0,-0.3974535,-10401.37
4.78,-0.04769443,-11.35651,-578382.4,0,0,0,-0.3974535,-10422.38
4.788,-0.04793053,-11.37167,-579154.6,0,0,0,-0.3994211,-10436.29
4.802,-0.04793053,-11.394,-580291.6,0,0,0,-0.3994211,-10456.78
4.816,-0.04816664,-11.40744,-580976.1,0,0,0,-0.4013887,-10469.12
4.828,-0.04840276,-11.42038,-581635.3,0,0,0,-0.4033563,-10480.99
4.844,-0.04840276,-11.44466,-582871.5,0,0,0,-0.4033563,-10503.27
4.862,-0.04863887,-11.46264,-583787.3,0,0,0,-0.4053239,-10519.77
4.882,-0.04887498,-11.48137,-584741.6,0,0,0,-0.4072915,-10536.97
4.904,-0.04911109,-11.50269,-585826.9,0,0,0,-0.4092591,-10556.53
4.916,-0.0493472,-11.51703,-586557.5,0,0,0,-0.4112267,-10569.69
4.93,-0.0493472,-11.5385,-587651.1,0,0,0,-0.4112267,-10589.4
4.946,-0.04958331,-11.5559,-588536.9,0,0,0,-0.4131942,-10605.36
4.96,-0.04981942,-11.57494,-589507.1,0,0,0,-0.4151618,-10622.84
4.982,-0.05005554,-11.59705,-590633.1,0,0,0,-0.4171295,-10643.13
5,-0.05005554,-11.62274,-591941.5,0,0,0,-0.4171295,-10666.71
5.01,-0.05029164,-11.63985,-592812.9,0,0,0,-0.419097,-10682.41
5.024,-0.05029164,-11.66228,-593955,0,0,0,-0.419097,-10702.99
5.034,-0.05052776,-11.67862,-594787.2,0,0,0,-0.4210646,-10717.99
5.05,-0.05052776,-11.70319,-596038.8,0,0,0,-0.4210646,-10740.54
5.064,-0.05076387,-11.71597,-596689.6,0,0,0,-0.4230323,-10752.27
5.086,-0.05099998,-11.73534,-597675.9,0,0,0,-0.4249998,-10770.04
5.102,-0.05123609,-11.75067,-598456.8,0,0,0,-0.4269674,-10784.11
5.124,-0.05123609,-11.77168,-599526.9,0,0,0,-0.4269674,-10803.4
5.136,-0.0514722,-11.79052,-600486.2,0,0,0,-0.428935,-10820.68
5.152,-0.0514722,-11.81249,-601605.2,0,0,0,-0.428935,-10840.85
5.174,-0.05170831,-11.82541,-602263.3,0,0,0,-0.4309026,-10852.71
5.19,-0.05194442,-11.8455,-603286.1,0,0,0,-0.4328702,-10871.14
5.208,-0.05218054,-11.86588,-604324.4,0,0,0,-0.4348378,-10889.85
5.226,-0.05218054,-11.89324,-605718,0,0,0,-0.4348378,-10914.96
5.234,-0.05241664,-11.9101,-606576.4,0,0,0,-0.4368054,-10930.43
5.258,-0.05241664,-11.93081,-607631,0,0,0,-0.4368054,-10949.43
5.27,-0.05265275,-11.94379,-608292.1,0,0,0,-0.4387729,-10961.35
5.286,-0.05288887,-11.95883,-609058.1,0,0,0,-0.4407406,-10975.15
5.302,-0.05288887,-11.98072,-610172.9,0,0,0,-0.4407406,-10995.24
5.312,-0.05312498,-11.99435,-610867.1,0,0,0,-0.4427081,-11007.75
5.336,-0.05336109,-12.01032,-611680.4,0,0,0,-0.4446757,-11022.4
5.354,-0.05336109,-12.03345,-612858.5,0,0,0,-0.4446757,-11043.63
5.366,-0.0535972,-12.05866,-614142.5,0,0,0,-0.4466433,-11066.77
5.384,-0.05383331,-12.07267,-614855.9,0,0,0,-0.4486109,-11079.63
5.41,-0.05406942,-12.0909,-615784.7,0,0,0,-0.4505785,-11096.36
5.422,-0.05406942,-12.11438,-616980.1,0,0,0,-0.4505785,-11117.9
5.434,-0.05430553,-12.13132,-617843.1,0,0,0,-0.4525461,-11133.45
5.448,-0.05430553,-12.15422,-619009.1,0,0,0,-0.4525461,-11154.47
5.458,-0.05454164,-12.16943,-619784,0,0,0,-0.4545137,-11168.43
5.482,-0.05454164,-12.19144,-620904.9,0,0,0,-0.4545137,-11188.63
5.492,-0.05477776,-12.20558,-621625.1,0,0,0,-0.4564813,-11201.6
5.504,-0.05477776,-12.22697,-622714.5,0,0,0,-0.4564813,-11221.24
5.518,-0.05501387,-12.24971,-623872.5,0,0,0,-0.4584489,-11242.1
5.534,-0.05524998,-12.26915,-624862.8,0,0,0,-0.4604165,-11259.95
5.568,-0.05548609,-12.28938,-625892.8,0,0,0,-0.4623841,-11278.51
5.582,-0.0557222,-12.30969,-626927.6,0,0,0,-0.4643517,-11297.16
5.608,-0.05595831,-12.33027,-627975.3,0,0,0,-0.4663192,-11316.04
5.624,-0.05595831,-12.3529,-629128,0,0,0,-0.4663192,-11336.81
5.636,-0.05619442,-12.37594,-630301.5,0,0,0,-0.4682868,-11357.95
5.654,-0.05643053,-12.39617,-631331.7,0,0,0,-0.4702544,-11376.52
5.676,-0.05666664,-12.41088,-632080.9,0,0,0,-0.472222,-11390.02
5.69,-0.05666664,-12.43334,-633224.6,0,0,0,-0.472222,-11410.63
5.7,-0.05690275,-12.45296,-634224.3,0,0,0,-0.4741896,-11428.64
5.712,-0.05690275,-12.4773,-635463.5,0,0,0,-0.4741896,-11450.97
5.72,-0.05713886,-12.49225,-636225.1,0,0,0,-0.4761572,-11464.7
5.744,-0.05737497,-12.51217,-637239.8,0,0,0,-0.4781248,-11482.98
5.766,-0.05761109,-12.53097,-638197,0,0,0,-0.4800924,-11500.23
5.78,-0.05761109,-12.55223,-639279.8,0,0,0,-0.4800924,-11519.74
5.79,-0.05761109,-12.57747,-640565.1,0,0,0,-0.4800924,-11542.9
5.798,-0.0578472,-12.59681,-641550.4,0,0,0,-0.48206,-11560.66
5.814,-0.05808331,-12.61002,-642223.2,0,0,0,-0.4840276,-11572.78
5.838,-0.05831942,-12.62629,-643051.8,0,0,0,-0.4859952,-11587.71
5.86,-0.05855553,-12.64927,-644222.3,0,0,0,-0.4879628,-11608.8
5.878,-0.05855553,-12.67156,-645357.2,0,0,0,-0.4879628,-11629.25
5.892,-0.05879164,-12.6932,-646459.6,0,0,0,-0.4899304,-11649.12
5.904,-0.05879164,-12.71611,-647626,0,0,0,-0.4899304,-11670.14
5.92,-0.05902775,-12.73817,-648749.8,0,0,0,-0.4918979,-11690.39
5.932,-0.05926386,-12.75424,-649568.2,0,0,0,-0.4938655,-11705.14
5.968,-0.05949998,-12.77781,-650768.5,0,0,0,-0.4958331,-11726.77
5.978,-0.05949998,-12.80335,-652069.1,0,0,0,-0.4958331,-11750.2
5.986,-0.05973608,-12.82637,-653241.8,0,0,0,-0.4978007,-11771.33
6,-0.05973608,-12.85128,-654510.5,0,0,0,-0.4978007,-11794.2
6.016,-0.05997219,-12.8669,-655305.8,0,0,0,-0.4997683,-11808.53
6.05,-0.06044442,-12.86403,-655159.8,0,0,0,-0.5037035,-11805.9
6.06,-0.06044442,-12.88503,-656229.4,0,0,0,-0.5037035,-11825.17
6.068,-0.06044442,-12.90883,-657441.5,0,0,0,-0.5037035,-11847.01
6.076,-0.06068053,-12.9287,-658453.2,0,0,0,-0.5056711,-11865.24
6.088,-0.06068053,-12.95619,-659853.4,0,0,0,-0.5056711,-11890.47
6.1,-0.06091664,-12.97229,-660673.1,0,0,0,-0.5076387,-11905.24
6.136,-0.06115275,-12.9779,-660959,0,0,0,-0.5096063,-11910.4
6.148,-0.06138886,-12.99809,-661987.4,0,0,0,-0.5115739,-11928.93
6.16,-0.06138886,-13.01928,-663066.7,0,0,0,-0.5115739,-11948.38
6.172,-0.06162497,-13.04237,-664242.3,0,0,0,-0.5135415,-11969.56
6.186,-0.06162497,-13.06525,-665407.7,0,0,0,-0.5135415,-11990.56
6.196,-0.06186108,-13.08225,-666273.8,0,0,0,-0.515509,-12006.17
6.22,-0.0620972,-13.10081,-667218.6,0,0,0,-0.5174766,-12023.19
6.244,-0.06233331,-13.12162,-668278.8,0,0,0,-0.5194442,-12042.3
6.26,-0.06233331,-13.14273,-669353.8,0,0,0,-0.5194442,-12061.67
6.27,-0.06256942,-13.156,-670029.4,0,0,0,-0.5214118,-12073.84
6.286,-0.06256942,-13.18045,-671274.8,0,0,0,-0.5214118,-12096.29
6.314,-0.06280552,-13.19777,-672156.8,0,0,0,-0.5233794,-12112.18
6.328,-0.06304164,-13.20906,-672731.7,0,0,0,-0.525347,-12122.54
6.338,-0.06327775,-13.22517,-673552.2,0,0,0,-0.5273145,-12137.32
6.348,-0.06327775,-13.24934,-674783.3,0,0,0,-0.5273145,-12159.51
6.358,-0.06327775,-13.27468,-676073.7,0,0,0,-0.5273145,-12182.76
6.368,-0.06351386,-13.29838,-677280.9,0,0,0,-0.5292822,-12204.51
6.404,-0.06374998,-13.31919,-678341,0,0,0,-0.5312498,-12223.62
6.42,-0.06398609,-13.33481,-679136.5,0,0,0,-0.5332174,-12237.95
6.438,-0.0642222,-13.35826,-680330.8,0,0,0,-0.535185,-12259.47
6.45,-0.0642222,-13.38566,-681726,0,0,0,-0.535185,-12284.62
6.458,-0.0644583,-13.40401,-682660.8,0,0,0,-0.5371525,-12301.46
6.47,-0.0644583,-13.42651,-683806.6,0,0,0,-0.5371525,-12322.11
6.49,-0.06469441,-13.44538,-684767.4,0,0,0,-0.5391201,-12339.42
6.506,-0.06493053,-13.46257,-685642.9,0,0,0,-0.5410877,-12355.2
6.52,-0.06493053,-13.48426,-686747.6,0,0,0,-0.5410877,-12375.1
6.534,-0.06516664,-13.49726,-687409.8,0,0,0,-0.5430554,-12387.04
6.546,-0.06540275,-13.51402,-688263.5,0,0,0,-0.5450229,-12402.42
6.562,-0.06540275,-13.53989,-689580.8,0,0,0,-0.5450229,-12426.16
6.592,-0.06587497,-13.54796,-689992,0,0,0,-0.5489581,-12433.57
6.612,-0.06587497,-13.57174,-691203.3,0,0,0,-0.5489581,-12455.39
6.622,-0.06611108,-13.58827,-692045,0,0,0,-0.5509257,-12470.56
6.638,-0.06611108,-13.61378,-693344.3,0,0,0,-0.5509257,-12493.97
6.646,-0.06634719,-13.62981,-694160.7,0,0,0,-0.5528933,-12508.69
6.66,-0.06634719,-13.65246,-695314,0,0,0,-0.5528933,-12529.47
6.672,-0.06658331,-13.66549,-695977.7,0,0,0,-0.5548609,-12541.43
6.708,-0.06681942,-13.67582,-696503.9,0,0,0,-0.5568284,-12550.91
6.718,-0.06705553,-13.69011,-697231.6,0,0,0,-0.5587961,-12564.03
6.73,-0.06705553,-13.71567,-698533.3,0,0,0,-0.5587961,-12587.48
6.738,-0.06729164,-13.7353,-699533.2,0,0,0,-0.5607637,-12605.5
6.75,-0.06729164,-13.76207,-700896.3,0,0,0,-0.5607637,-12630.06
6.76,-0.06752774,-13.78133,-701877.6,0,0,0,-0.5627312,-12647.74
6.774,-0.06752774,-13.80725,-703197.4,0,0,0,-0.5627312,-12671.53
6.798,-0.06799997,-13.81479,-703581.6,0,0,0,-0.5666664,-12678.45
6.822,-0.06823608,-13.83783,-704755,0,0,0,-0.568634,-12699.6
6.83,-0.06823608,-13.85914,-705840.3,0,0,0,-0.568634,-12719.15
6.84,-0.06823608,-13.882,-707004.5,0,0,0,-0.568634,-12740.13
6.852,-0.0684722,-13.89927,-707884.1,0,0,0,-0.5706016,-12755.98
6.866,-0.0687083,-13.9178,-708827.7,0,0,0,-0.5725692,-12772.98
6.896,-0.06894442,-13.90126,-707985.2,0,0,0,-0.5745368,-12757.8
6.916,-0.06918052,-13.92658,-709274.9,0,0,0,-0.5765043,-12781.04
6.924,-0.06918052,-13.95825,-710887.8,0,0,0,-0.5765043,-12810.11
6.932,-0.06918052,-13.98711,-712357.8,0,0,0,-0.5765043,-12836.6
6.942,-0.06941664,-14.01252,-713651.6,0,0,0,-0.578472,-12859.91
6.954,-0.06941664,-14.03423,-714757.4,0,0,0,-0.578472,-12879.84
6.97,-0.06965275,-14.05803,-715969.8,0,0,0,-0.5804396,-12901.68
7.01,-0.07012497,-14.06185,-716163.9,0,0,0,-0.5843747,-12905.18
7.022,-0.07012497,-14.08928,-717561.2,0,0,0,-0.5843747,-12930.36
7.032,-0.07012497,-14.11395,-718817.4,0,0,0,-0.5843747,-12953
7.04,-0.07036108,-14.1324,-719757.4,0,0,0,-0.5863424,-12969.94
7.054,-0.07036108,-14.15728,-721024.5,0,0,0,-0.5863424,-12992.77
7.082,-0.0708333,-14.1565,-720984.6,0,0,0,-0.5902776,-12992.05
7.104,-0.07106941,-14.18026,-722194.9,0,0,0,-0.5922451,-13013.86
7.114,-0.07106941,-14.20451,-723429.8,0,0,0,-0.5922451,-13036.11
7.124,-0.07130553,-14.22859,-724656.3,0,0,0,-0.5942127,-13058.21
7.136,-0.07130553,-14.2528,-725889.4,0,0,0,-0.5942127,-13080.43
7.148,-0.07154164,-14.2753,-727035.3,0,0,0,-0.5961803,-13101.08
7.162,-0.07177775,-14.29158,-727864,0,0,0,-0.5981479,-13116.02
7.182,-0.07201386,-14.31357,-728984.1,0,0,0,-0.6001155,-13136.2
7.194,-0.07201386,-14.33704,-730179.6,0,0,0,-0.6001155,-13157.74
7.208,-0.07224997,-14.36278,-731490.6,0,0,0,-0.6020831,-13181.37
7.22,-0.07248608,-14.38167,-732452.4,0,0,0,-0.6040506,-13198.7
7.232,-0.07248608,-14.4074,-733763.1,0,0,0,-0.6040506,-13222.32
7.242,-0.07272219,-14.42317,-734566,0,0,0,-0.6060182,-13236.79
7.264,-0.0729583,-14.44064,-735455.8,0,0,0,-0.6079859,-13252.82
7.288,-0.07319441,-14.45493,-736183.8,0,0,0,-0.6099535,-13265.94
7.31,-0.07319441,-14.47853,-737385.5,0,0,0,-0.6099535,-13287.59
7.326,-0.07343053,-14.49374,-738160,0,0,0,-0.6119211,-13301.55
7.342,-0.07366664,-14.51289,-739135.2,0,0,0,-0.6138886,-13319.12
7.372,-0.07390274,-14.53111,-740063.5,0,0,0,-0.6158562,-13335.85
7.386,-0.07390274,-14.55335,-741196.3,0,0,0,-0.6158562,-13356.26
7.398,-0.07413886,-14.57153,-742121.9,0,0,0,-0.6178238,-13372.94
7.42,-0.07413886,-14.59251,-743190.3,0,0,0,-0.6178238,-13392.2
7.438,-0.07437497,-14.60791,-743974.7,0,0,0,-0.6197914,-13406.33
7.452,-0.07461108,-14.61994,-744587.2,0,0,0,-0.621759,-13417.37
7.474,-0.07461108,-14.64264,-745743.6,0,0,0,-0.621759,-13438.2
7.488,-0.07484719,-14.65904,-746578.9,0,0,0,-0.6237266,-13453.26
7.504,-0.0750833,-14.6797,-747631.3,0,0,0,-0.6256942,-13472.22
7.53,-0.07531942,-14.69967,-748648.3,0,0,0,-0.6276618,-13490.55
7.546,-0.07531942,-14.7202,-749693.8,0,0,0,-0.6276618,-13509.39
7.556,-0.07555552,-14.73642,-750519.6,0,0,0,-0.6296294,-13524.27
7.572,-0.07555552,-14.76026,-751733.8,0,0,0,-0.6296294,-13546.15
7.59,-0.07579163,-14.77962,-752719.7,0,0,0,-0.6315969,-13563.91
7.602,-0.07602775,-14.79802,-753657.1,0,0,0,-0.6335645,-13580.81
7.628,-0.07626386,-14.81919,-754734.9,0,0,0,-0.6355321,-13600.23
7.644,-0.07626386,-14.83971,-755780,0,0,0,-0.6355321,-13619.06
7.656,-0.07649997,-14.86308,-756970.6,0,0,0,-0.6374997,-13640.51
7.672,-0.07673609,-14.88339,-758004.6,0,0,0,-0.6394674,-13659.15
7.694,-0.07697219,-14.90722,-759218.4,0,0,0,-0.6414349,-13681.02
7.708,-0.07697219,-14.93065,-760411.9,0,0,0,-0.6414349,-13702.52
7.736,-0.0772083,-14.95026,-761410.7,0,0,0,-0.6434025,-13720.52
7.748,-0.07744441,-14.96709,-762267.7,0,0,0,-0.6453701,-13735.97
7.762,-0.07744441,-14.98893,-763380.1,0,0,0,-0.6453701,-13756.01
7.772,-0.07768052,-15.00103,-763996.1,0,0,0,-0.6473377,-13767.11
7.786,-0.07791664,-15.01805,-764863.1,0,0,0,-0.6493053,-13782.73
7.802,-0.07791664,-15.04289,-766128.1,0,0,0,-0.6493053,-13805.53
7.816,-0.07815275,-15.06628,-767319.1,0,0,0,-0.651273,-13826.99
7.844,-0.07838886,-15.08731,-768390.3,0,0,0,-0.6532405,-13846.29
7.856,-0.07862496,-15.11351,-769724.6,0,0,0,-0.655208,-13870.34
7.868,-0.07862496,-15.13874,-771009.6,0,0,0,-0.655208,-13893.49
7.878,-0.07886108,-15.1522,-771695,0,0,0,-0.6571757,-13905.85
7.898,-0.07886108,-15.17707,-772961.6,0,0,0,-0.6571757,-13928.67
7.914,-0.07909719,-15.19218,-773731.5,0,0,0,-0.6591433,-13942.54
7.942,-0.0793333,-15.19775,-774015.2,0,0,0,-0.6611109,-13947.66
7.95,-0.07956942,-15.21549,-774918.7,0,0,0,-0.6630785,-13963.94
7.958,-0.07956942,-15.23594,-775960.1,0,0,0,-0.6630785,-13982.7
7.97,-0.07956942,-15.26101,-777236.7,0,0,0,-0.6630785,-14005.71
7.978,-0.07980552,-15.27584,-777992.1,0,0,0,-0.665046,-14019.32
7.998,-0.08004164,-15.28896,-778660.4,0,0,0,-0.6670136,-14031.36
8.024,-0.08027774,-15.30568,-779511.8,0,0,0,-0.6689812,-14046.7
8.04,-0.08027774,-15.33001,-780751,0,0,0,-0.6689812,-14069.03
8.056,-0.08051386,-15.35221,-781881.4,0,0,0,-0.6709488,-14089.4
8.068,-0.08051386,-15.37428,-783005.9,0,0,0,-0.6709488,-14109.67
8.08,-0.08074997,-15.40059,-784345.8,0,0,0,-0.6729164,-14133.81
8.1,-0.08098608,-15.40675,-784659.2,0,0,0,-0.674884,-14139.46
8.132,-0.08122219,-15.42802,-785742.4,0,0,0,-0.6768516,-14158.98
8.15,-0.0814583,-15.4516,-786943.8,0,0,0,-0.6788192,-14180.63
8.164,-0.0814583,-15.47691,-788232.4,0,0,0,-0.6788192,-14203.85
8.172,-0.0814583,-15.50025,-789421.3,0,0,0,-0.6788192,-14225.27
8.18,-0.08169441,-15.51909,-790380.6,0,0,0,-0.6807867,-14242.56
8.222,-0.08216663,-15.51912,-790382.3,0,0,0,-0.6847219,-14242.59
8.234,-0.08216663,-15.54417,-791658.2,0,0,0,-0.6847219,-14265.58
8.248,-0.08240275,-15.56828,-792886,0,0,0,-0.6866896,-14287.7
8.258,-0.08240275,-15.59307,-794148.8,0,0,0,-0.6866896,-14310.46
8.268,-0.08240275,-15.61485,-795257.7,0,0,0,-0.6866896,-14330.44
8.28,-0.08263885,-15.63159,-796110.2,0,0,0,-0.6886571,-14345.8
8.318,-0.08311108,-15.64938,-797016.4,0,0,0,-0.6925923,-14362.13
8.33,-0.08311108,-15.67563,-798353.3,0,0,0,-0.6925923,-14386.22
8.34,-0.08334719,-15.69149,-799160.9,0,0,0,-0.6945599,-14400.78
8.356,-0.08334719,-15.71332,-800273.1,0,0,0,-0.6945599,-14420.82
8.368,-0.0835833,-15.73707,-801482.6,0,0,0,-0.6965275,-14442.61
8.384,-0.08381941,-15.75918,-802608.5,0,0,0,-0.6984951,-14462.9
8.418,-0.08405552,-15.76618,-802964.9,0,0,0,-0.7004626,-14469.33
8.43,-0.08405552,-15.79006,-804181.4,0,0,0,-0.7004626,-14491.25
8.438,-0.08429163,-15.80509,-804946.6,0,0,0,-0.7024302,-14505.03
8.45,-0.08429163,-15.83043,-806237.3,0,0,0,-0.7024302,-14528.29
8.46,-0.08452775,-15.85351,-807412.7,0,0,0,-0.7043979,-14549.47
8.478,-0.08476386,-15.86882,-808192.6,0,0,0,-0.7063655,-14563.53
8.516,-0.08499997,-15.87166,-808337.3,0,0,0,-0.708333,-14566.13
8.526,-0.08523608,-15.88636,-809085.6,0,0,0,-0.7103007,-14579.62
8.536,-0.08523608,-15.9086,-810218.4,0,0,0,-0.7103007,-14600.03
8.544,-0.08523608,-15.93017,-811316.8,0,0,0,-0.7103007,-14619.82
8.552,-0.08547218,-15.94838,-812244.4,0,0,0,-0.7122682,-14636.54
8.572,-0.08547218,-15.9698,-813335.3,0,0,0,-0.7122682,-14656.2
8.588,-0.0857083,-15.9846,-814089.2,0,0,0,-0.7142358,-14669.78
8.606,-0.08594441,-16.00746,-815253.2,0,0,0,-0.7162035,-14690.76
8.622,-0.08594441,-16.02965,-816383.6,0,0,0,-0.7162035,-14711.13
8.632,-0.08618053,-16.04221,-817023.2,0,0,0,-0.7181711,-14722.65
8.646,-0.08641663,-16.05503,-817675.8,0,0,0,-0.7201386,-14734.41
8.69,-0.08665274,-16.06824,-818349,0,0,0,-0.7221062,-14746.54
8.698,-0.08688885,-16.08465,-819184.6,0,0,0,-0.7240738,-14761.6
8.706,-0.08688885,-16.10517,-820229.4,0,0,0,-0.7240738,-14780.43
8.72,-0.08688885,-16.12775,-821379.5,0,0,0,-0.7240738,-14801.15
8.734,-0.08712496,-16.14062,-822034.9,0,0,0,-0.7260414,-14812.96
8.768,-0.08759719,-16.14144,-822076.8,0,0,0,-0.7299766,-14813.72
8.792,-0.0878333,-16.13013,-821500.8,0,0,0,-0.7319442,-14803.34
8.818,-0.08806941,-16.11225,-820589.9,0,0,0,-0.7339118,-14786.93
8.84,-0.08830551,-16.09889,-819909.8,0,0,0,-0.7358793,-14774.67
8.862,-0.08854163,-16.11085,-820518.9,0,0,0,-0.7378469,-14785.65
8.892,-0.08877774,-16.12901,-821443.9,0,0,0,-0.7398145,-14802.31
8.904,-0.08877774,-16.15409,-822721.3,0,0,0,-0.7398145,-14825.33
8.93,-0.08924997,-16.16659,-823357.5,0,0,0,-0.7437497,-14836.8
8.948,-0.08924997,-16.18927,-824512.9,0,0,0,-0.7437497,-14857.62
8.964,-0.08948608,-16.20647,-825388.6,0,0,0,-0.7457173,-14873.4
8.976,-0.08972218,-16.21928,-826041.1,0,0,0,-0.7476848,-14885.16
8.99,-0.08972218,-16.24298,-827247.9,0,0,0,-0.7476848,-14906.9
9.002,-0.08995829,-16.26539,-828389.6,0,0,0,-0.7496524,-14927.47
9.024,-0.08995829,-16.28589,-829433.4,0,0,0,-0.7496524,-14946.29
9.04,-0.09019441,-16.29801,-830050.8,0,0,0,-0.7516201,-14957.41
9.05,-0.09043052,-16.31493,-830912.8,0,0,0,-0.7535877,-14972.94
9.074,-0.09066664,-16.32718,-831536.4,0,0,0,-0.7555553,-14984.18
9.108,-0.09090274,-16.34478,-832432.9,0,0,0,-0.7575228,-15000.33
9.122,-0.09113885,-16.36528,-833476.7,0,0,0,-0.7594904,-15019.14
9.14,-0.09113885,-16.38568,-834515.9,0,0,0,-0.7594904,-15037.87
9.154,-0.09137496,-16.40484,-835491.7,0,0,0,-0.761458,-15055.45
9.168,-0.09161107,-16.41976,-836251.3,0,0,0,-0.7634256,-15069.14
9.206,-0.09184719,-16.43437,-836995.7,0,0,0,-0.7653932,-15082.56
9.236,-0.09231941,-16.44681,-837629.2,0,0,0,-0.7693284,-15093.97
9.26,-0.09255552,-16.45607,-838100.6,0,0,0,-0.771296,-15102.46
9.294,-0.09279162,-16.45902,-838250.9,0,0,0,-0.7732635,-15105.17
9.32,-0.09302774,-16.44702,-837639.8,0,0,0,-0.7752311,-15094.16
9.33,-0.09326385,-16.42234,-836382.9,0,0,0,-0.7771988,-15071.51
9.338,-0.09326385,-16.38668,-834567,0,0,0,-0.7771988,-15038.79
9.342,-0.09326385,-16.36363,-833393.1,0,0,0,-0.7771988,-15017.64
9.346,-0.09326385,-16.33896,-832136.2,0,0,0,-0.7771988,-14994.99
9.35,-0.09326385,-16.31371,-830850.4,0,0,0,-0.7771988,-14971.82
9.354,-0.09349996,-16.28866,-829574.8,0,0,0,-0.7791663,-14948.83
9.358,-0.09349996,-16.2653,-828384.8,0,0,0,-0.7791663,-14927.39
9.364,-0.09349996,-16.23585,-826885.1,0,0,0,-0.7791663,-14900.36
9.372,-0.09349996,-16.21013,-825575.3,0,0,0,-0.7791663,-14876.76
9.388,-0.09373607,-16.18999,-824549.3,0,0,0,-0.7811339,-14858.27
9.418,-0.09397218,-16.19221,-824662.8,0,0,0,-0.7831016,-14860.32
9.45,-0.0944444,-16.19538,-824823.9,0,0,0,-0.7870367,-14863.22
9.496,-0.09491662,-16.21449,-825797.4,0,0,0,-0.7909719,-14880.76
9.51,-0.09491662,-16.23783,-826985.7,0,0,0,-0.7909719,-14902.18
9.52,-0.09515274,-16.25385,-827801.7,0,0,0,-0.7929395,-14916.88
9.56,-0.09538885,-16.26654,-828448.2,0,0,0,-0.7949071,-14928.53
9.59,-0.09586107,-16.28579,-829428.7,0,0,0,-0.7988423,-14946.2
9.6,-0.09586107,-16.30818,-830568.8,0,0,0,-0.7988423,-14966.74
9.608,-0.09586107,-16.32965,-831662.3,0,0,0,-0.7988423,-14986.45
9.626,-0.09609718,-16.35255,-832828.8,0,0,0,-0.8008099,-15007.47
9.658,-0.0965694,-16.3622,-833320.1,0,0,0,-0.804745,-15016.32
9.686,-0.09680552,-16.38389,-834424.7,0,0,0,-0.8067126,-15036.23
9.698,-0.09680552,-16.40953,-835730.5,0,0,0,-0.8067126,-15059.76
9.712,-0.09704163,-16.42864,-836703.6,0,0,0,-0.8086802,-15077.29
9.728,-0.09727774,-16.45074,-837829.6,0,0,0,-0.8106478,-15097.58
9.75,-0.09751385,-16.45581,-838087.8,0,0,0,-0.8126154,-15102.23
9.77,-0.09774995,-16.47007,-838813.8,0,0,0,-0.8145829,-15115.32
9.78,-0.09774995,-16.49331,-839997.6,0,0,0,-0.8145829,-15136.65
9.79,-0.09774995,-16.51758,-841233.5,0,0,0,-0.8145829,-15158.92
9.798,-0.09798607,-16.53301,-842019.1,0,0,0,-0.8165506,-15173.08
9.812,-0.09822218,-16.55144,-842958.1,0,0,0,-0.8185182,-15190
9.828,-0.09822218,-16.57267,-844039,0,0,0,-0.8185182,-15209.48
9.854,-0.09869441,-16.58099,-844463.1,0,0,0,-0.8224534,-15217.12
9.874,-0.09869441,-16.60941,-845910.5,0,0,0,-0.8224534,-15243.2
9.88,-0.09893051,-16.62446,-846677,0,0,0,-0.8244209,-15257.01
9.888,-0.09893051,-16.64478,-847711.7,0,0,0,-0.8244209,-15275.66
9.896,-0.09916662,-16.65988,-848480.9,0,0,0,-0.8263885,-15289.52
9.912,-0.09916662,-16.68471,-849745.6,0,0,0,-0.8263885,-15312.31
9.936,-0.09963885,-16.69454,-850245.9,0,0,0,-0.8303237,-15321.32
9.958,-0.09987496,-16.71332,-851202.5,0,0,0,-0.8322913,-15338.56
9.974,-0.09987496,-16.73773,-852445.7,0,0,0,-0.8322913,-15360.96
9.978,-0.1001111,-16.74446,-852788.2,0,0,0,-0.834259,-15367.13